Traceback (most recent call last):
  File "/homes/ogkourlias/Documents/BDC/Assignment6/assignment6.py", line 509, in <module>
    sys.exit(main(sys.argv))
             ^^^^^^^^^^^^^^
  File "/homes/ogkourlias/Documents/BDC/Assignment6/assignment6.py", line 501, in main
    headers = header_subset(args.input_header, args.comp_header)
              ^^^^^^^^^^^^^^^^^^^^^^^^^^^^^^^^^^^^^^^^^^^^^^^^^^
  File "/homes/ogkourlias/Documents/BDC/Assignment6/assignment6.py", line 112, in header_subset
    for header_i in np.genfromtxt(input_headers_r, delimiter="\t", dtype=str):
                    ^^^^^^^^^^^^^^^^^^^^^^^^^^^^^^^^^^^^^^^^^^^^^^^^^^^^^^^^^
  File "/homes/ogkourlias/venvs/bdc/lib/python3.11/site-packages/numpy/lib/npyio.py", line 1980, in genfromtxt
    fid = np.lib._datasource.open(fname, 'rt', encoding=encoding)
          ^^^^^^^^^^^^^^^^^^^^^^^^^^^^^^^^^^^^^^^^^^^^^^^^^^^^^^^
  File "/homes/ogkourlias/venvs/bdc/lib/python3.11/site-packages/numpy/lib/_datasource.py", line 193, in open
    return ds.open(path, mode, encoding=encoding, newline=newline)
           ^^^^^^^^^^^^^^^^^^^^^^^^^^^^^^^^^^^^^^^^^^^^^^^^^^^^^^^
  File "/homes/ogkourlias/venvs/bdc/lib/python3.11/site-packages/numpy/lib/_datasource.py", line 533, in open
    raise FileNotFoundError(f"{path} not found.")
FileNotFoundError: data/subset1/chr21.vcf.gz.txt not found.
Traceback (most recent call last):
  File "/homes/ogkourlias/Documents/BDC/Assignment6/assignment6.py", line 509, in <module>
    sys.exit(main(sys.argv))
             ^^^^^^^^^^^^^^
  File "/homes/ogkourlias/Documents/BDC/Assignment6/assignment6.py", line 501, in main
    headers = header_subset(args.input_header, args.comp_header)
              ^^^^^^^^^^^^^^^^^^^^^^^^^^^^^^^^^^^^^^^^^^^^^^^^^^
  File "/homes/ogkourlias/Documents/BDC/Assignment6/assignment6.py", line 112, in header_subset
    for header_i in np.genfromtxt(input_headers_r, delimiter="\t", dtype=str):
                    ^^^^^^^^^^^^^^^^^^^^^^^^^^^^^^^^^^^^^^^^^^^^^^^^^^^^^^^^^
  File "/homes/ogkourlias/venvs/bdc/lib/python3.11/site-packages/numpy/lib/npyio.py", line 1980, in genfromtxt
    fid = np.lib._datasource.open(fname, 'rt', encoding=encoding)
          ^^^^^^^^^^^^^^^^^^^^^^^^^^^^^^^^^^^^^^^^^^^^^^^^^^^^^^^
  File "/homes/ogkourlias/venvs/bdc/lib/python3.11/site-packages/numpy/lib/_datasource.py", line 193, in open
    return ds.open(path, mode, encoding=encoding, newline=newline)
           ^^^^^^^^^^^^^^^^^^^^^^^^^^^^^^^^^^^^^^^^^^^^^^^^^^^^^^^
  File "/homes/ogkourlias/venvs/bdc/lib/python3.11/site-packages/numpy/lib/_datasource.py", line 533, in open
    raise FileNotFoundError(f"{path} not found.")
FileNotFoundError: data/subset2/chr21.vcf.gz.txt not found.
